<?xml version="1.0" ?>
<robot name="gripper" xmlns:xacro="http://www.ros.org/wiki/xacro">

<xacro:include filename="$(find gripper_description)/urdf/materials.xacro" />
<xacro:include filename="$(find gripper_description)/urdf/gripper.trans" />
<xacro:include filename="$(find gripper_description)/urdf/gripper.gazebo" />
<link name="base_link">
  <inertial>
    <origin xyz="0.0023458559811001794 0.005741468367557181 -0.023747939953084603" rpy="0 0 0"/>
    <mass value="0.4314487172538147"/>
    <inertia ixx="0.000183" iyy="0.000342" izz="0.000259" ixy="-3.2e-05" iyz="1.8e-05" ixz="4.3e-05"/>
  </inertial>
  <visual>
    <origin xyz="0 0 0" rpy="0 0 0"/>
    <geometry>
      <mesh filename="file://$(find gripper_description)/meshes/base_link.stl" scale="0.001 0.001 0.001"/>
    </geometry>
    <material name="silver"/>
  </visual>
  <collision>
    <origin xyz="0 0 0" rpy="0 0 0"/>
    <geometry>
      <mesh filename="file://$(find gripper_description)/meshes/base_link.stl" scale="0.001 0.001 0.001"/>
    </geometry>
  </collision>
</link>

<link name="right_gripper_1">
  <inertial>
    <origin xyz="0.016547314639781804 5.6788901515353275e-18 -0.01756777493606139" rpy="0 0 0"/>
    <mass value="0.12277399999999998"/>
    <inertia ixx="2.1e-05" iyy="2.3e-05" izz="1.1e-05" ixy="0.0" iyz="-0.0" ixz="6e-06"/>
  </inertial>
  <visual>
    <origin xyz="0.052 -0.0 0.061" rpy="0 0 0"/>
    <geometry>
      <mesh filename="file://$(find gripper_description)/meshes/right_gripper_1.stl" scale="0.001 0.001 0.001"/>
    </geometry>
    <material name="silver"/>
  </visual>
  <collision>
    <origin xyz="0.052 -0.0 0.061" rpy="0 0 0"/>
    <geometry>
      <mesh filename="file://$(find gripper_description)/meshes/right_gripper_1.stl" scale="0.001 0.001 0.001"/>
    </geometry>
  </collision>
</link>

<link name="left_gripper_1">
  <inertial>
    <origin xyz="-0.016547314516228415 7.950446212149488e-18 -0.01756777493606136" rpy="0 0 0"/>
    <mass value="0.12277399999999954"/>
    <inertia ixx="2.1e-05" iyy="2.3e-05" izz="1.1e-05" ixy="0.0" iyz="0.0" ixz="-6e-06"/>
  </inertial>
  <visual>
    <origin xyz="-0.052 -0.0 0.061" rpy="0 0 0"/>
    <geometry>
      <mesh filename="file://$(find gripper_description)/meshes/left_gripper_1.stl" scale="0.001 0.001 0.001"/>
    </geometry>
    <material name="silver"/>
  </visual>
  <collision>
    <origin xyz="-0.052 -0.0 0.061" rpy="0 0 0"/>
    <geometry>
      <mesh filename="file://$(find gripper_description)/meshes/left_gripper_1.stl" scale="0.001 0.001 0.001"/>
    </geometry>
  </collision>
</link>

<joint name="Slider 1" type="prismatic">
  <origin xyz="-0.052 0.0 -0.061" rpy="0 0 0"/>
  <parent link="base_link"/>
  <child link="right_gripper_1"/>
  <axis xyz="-1.0 0.0 0.0"/>
  <limit upper="-0.02" lower="0.0" effort="100" velocity="100"/>
</joint>

<joint name="Slider 2" type="prismatic">
  <origin xyz="0.052 0.0 -0.061" rpy="0 0 0"/>
  <parent link="base_link"/>
  <child link="left_gripper_1"/>
  <axis xyz="1.0 0.0 0.0"/>
  <limit upper="-0.02" lower="0.0" effort="100" velocity="100"/>
</joint>

</robot>
